<?xml version="1.0"?>
<robot xmlns:xacro="http://www.ros.org/wiki/xacro">
	<xacro:macro name="wheel" params="name parent xyz:='0 0 0' rpy:='0 0 0'">
		<xacro:property name="radius" value="0.07825"/>
		<xacro:property name="length" value="0.085"/>
		<xacro:property name="rho" value="1046.3516"/>
		<xacro:property name="mass" value="2.1"/>

		<joint name="${name}_joint" type="continuous">
			<axis xyz="0 0 1" />
			<origin xyz="${xyz}" rpy="${rpy}" />
			<parent link="${parent}" />
			<child link="${name}" />
			<dynamics damping="1.0" friction="0.0" />
		</joint>

		<link name="${name}">
			<!-- Make the wheel has one point contact to the ground -->
			<xacro:inertia_sphere rho="${rho}" radius="${radius}" />
			<xacro:collision_sphere radius="${radius}" />
			<!-- Show as a cylinder -->
			<xacro:visual_cylinder radius="${radius}" length="${length}" />
		</link>
	</xacro:macro>
</robot>
